Workbook

Sheet Análisis Evaluación Crediticio
B4: ANÁLISIS Y EVALUACIÓN CREDITICIO Para uso exclusivo del Departamento de Crédito
B5: Cliente N° | C5: Apellidos y Nombres | H5: Destino | I5: COMPRA DE TERRENO | M5: Tipo de Préstamo: | O5: 4 | P5: =VLOOKUP(O5,'TIPOS DE PRÉSTAMO'!A2:B44,2,0) -> ORDINARIO SIN GARANTE
B6: 228566 | C6: NAVAS PEÑAHERRERA GABRIEL HUMBERTO | M6: Tipo de Cartera: | O6: 4 | P6: =VLOOKUP(O6,'TIPO DE CARTERA'!B29:C43,2,0) -> CONSUMO
M7: Oficina: | O7: 7 | P7: =VLOOKUP(O7,'CÓDIGO OFICINA'!A5:B18,2) -> LAGO AGRIO
B8: Monto | D8: Interés | E8: Plazo (meses) | G8: Pagos (días) | H8: 30 | J8: Cuota Decreciente | K8: Cuota Fija | M8: Oficial de Negocios asignado | Q8: Fecha
B9: 20000 | D9: 0.155 | E9: 48 | G9: =IF(H8=30,"Pagos Mensuales",IF(H8=60,"Pagos Bimestrales",IF(H8=90,"Pagos Trimestrales",IF(H8=180,"Pagos Semestrales",IF(H8=360,"Pagos Anuales"))))) -> Pagos Mensuales | J9: =IF(E9>0,B9/(E9*30/H8)+B9*D9*H8/360,"") -> 675 | K9: =IF(E9>0,(B9*D9*H8/360)/(1-(1+(D9*H8/360))^-(30*E9/H8)),"") -> 561.69718 | M9: 7-03 | N9: =VLOOKUP(M9,'OFICIALES DE NEGOCIO'!D3:E95,2,0) -> JARAMILLO JIMENEZ CARLOS ISRAEL | Q9: 46077
B10: Subsegmentación de Cartera | D10: Descripción
B11: 4-0 | C11: =VLOOKUP(B11,'SEGMENTOS DE CREDITO'!B6:C14,2,0) -> CONSUMO | D11: =VLOOKUP(C11,'SEGMENTOS DE CREDITO'!C6:D14,2,0) -> Son aquellas operaciones otorgadas a personas naturales, destinado a la compra de bienes, servicios o gastos no relacionados con una actividad productiva, comercial y otras compras y gastos, se incluyen los créditos prendarios de joyas, así como para adquisición de vehículos livianos que no sean de uso para una actividad productiva y comercial.
B13: COMENTARIOS DE CARÁCTER
B14: Segundo credito a solicitar en la CPMV. En el sistema Financiero Nacional refleja operaciones vigentes en: CPMV 11217.14 USD. Su segmentación es 911 AA, reporte crediticio favorable para un crédito ordinario sin garante. La vivienda en la que reside es arrendada, ubicada en el cantón de Lago Agrio, parroquia Nueva Loja, provincia de Sucumbíos, en el barrio Santa Isabel, a lado de la pizzeria like. Solicitante, goza de buen estado de salud con 23 años de edad, de estado civil soltero, no posee cargas familiares menores de edad; su nivel de instrucción es bachiller, labora de manera independiente. Buenas referencias de quienes la conocen, amigos y familiares cercanos al socio: señora, Deysi Peñaherrera (madre); Israel Peñaherrera (tio) y Wilson Navas (padre); quienes dan testimonio de conocer a al socio por algún tiempo, mismo que ha demostrado ser una persona proba en sus obligaciones | R14: <
B20: COMENTARIOS DE CAPACIDAD DE PAGO
B21: Solicitante es independiente, propietario de ELECTROSERVICIOS NAVAS, actividad relacionada con la electromecánica, se respalda con la presentación RUC y últimas tres declaraciones. Según el levantamiento de información sus ingresos se consideran por el valor de 1389 USD, sus gastos personales mensuales son de 595.71 USD generando un excedente mensual de 793.29 USD. Según la evaluación y luego de aplicar el castigo del 30% que es de acuerdo a la fuente de ingresos se comprueba que éstos son suficientes para cubrir las cuota del crédito; es decir que la cuota propuesta es de 481.06 USD VS el excedente 793.29 USD se compromete en un 60%. Se comprueba que el socio tiene la capacidad de pago adecuada para esta operación crediticia. Los pagos se realizarán de los ingresos mensuales percibidos por la solicitante.
B27: COMENTARIOS DE CAPITAL
B28: Sus activos están conformados por sus bienes muebles, con un total de activos de 22335.18 USD. Posee pasivos por 11271.14 USD, por lo tanto, su patrimonio es de 11064.04 USD. El monto recomendado para aprobación es de 20000 USD. Se determina que socio se encuentra en condiciones favorables, capacidad de pago acorde al monto solicitado y un patrimonio que cumple con el 200% de la política exigida en la institución.
B33: COMENTARIOS DE COLATERAL
B34: El garante, señor, PEÑAHERRERA MUÑOZ ISRAEL ALFONSO, de estado civil casado, sus ingresos son de actividad de COMERCIANTE DE ROPA y ARTÍCULOS para el hogar, se adjunta RUC,declaracion y facturas. Mantienen obligaciones vigentes en: PICHINCHA VISA 10695.90 USD; PACIFICO VISA 226.66 USD; PICHINCHA 20908.84 USD; PICHINCHA 7503.70 USD; PICHINCHA 5885.95 USD; PICHINCHA 5217.77 USD; COOP 23 DE JULIO 14149.71 USD y CONECEL 36 USD. Presenta activos por USD 155650, resultando en un patrimonio de USD 91025.47 USD. Su segmentación de riesgo AA 940. Con base en el levantamiento de información, sus ingresos mensuales ascienden a USD 4342.50, mientras que los gastos personales se consideran por 3563.38 USD , generando un excedente de USD 779.12. En consecuencia, el garante cuenta con capacidad de pago suficiente para respaldar la cuota del deudor principal.
B39: COMENTARIO DE CONDICIONES GENERALES
B40: Se recomienda la aprobación del crédito, socio con actividad estable; garante posee patrimonio. En el sistema financiero nacional no registra, reporte por mora ni vencimientos. Sector económico estable. Se recomienda su aprobación por tiempo y monto propuesto. Revisadas páginas de la Judicatura, no se encuentra inconvenientes para el otorgamiento de la operación crediticia
B45: ORDINARIO / CONSUMO: Crédito bajo reglamento. Cumple con todos los requisitos, se conceda un monto de VEINTE MIL 00/100 (USD 20.000.00) a un plazo de 60 MESES, pagos mensuales. Se recomienda su aprobación por tiempo y monto propuesto, cliente cumple con todos los requisitos.
P51: =+N9 -> JARAMILLO JIMENEZ CARLOS ISRAEL
P52: =+Q9 -> 46077
B53: RESOLUCIÓN DEL COMITÉ DE CRÉDITO OFICINA | Q53: COMITÉ DE CRÉDITO OFICINA - Nº Acta :
B55: APROBADO: | D55: OBSERVACIONES:
B57: SUSPENSO:
B59: NEGADO:
B61: FECHA:
D62: PRESIDENTE | J62: SECRETARIO | O62: VOCAL
B63: RESOLUCIÓN DEL COMITÉ DE CRÉDITO EJECUTIVO O GENERAL | Q63: COMITÉ DE CRÉDITO EJECUTIVO O GENERAL- Nº Acta :
B65: APROBADO: | D65: OBSERVACIONES:
B67: SUSPENSO:
B69: NEGADO:
B71: FECHA:
D72: PRESIDENTE | J72: SECRETARIO | O72: VOCAL
B73: RESOLUCIÓN DEL CONSEJO DE ADMINISTRACIÓN
D75: OBSERVACIONES:
B76: APROBADO:
B77: SUSPENSO:
B78: NEGADO:
B79: FECHA:
D80: PRESIDENTE | J80: SECRETARIO | O80: VOCAL

Sheet ENTRADA DE PARAMETROS
A2: PARAMETROS DE CALIFICACION DE RIESGO | D2: PARAMETROS DE CALIFICACION PARA CAPACIDAD DE PAGO
B3: Valorar sobre 10 | E3: Valorar sobre 10
A4: 1. Carácter | B4: 29 | D4: 3.1 Capacidad de pago | E4: =10+10+10 -> 30
A5: 2. Capacidad de Gestión | B5: 21 | D5: 3.2 Rentabilidad sobre Capital | E5: =9+8+8 -> 25
A6: 3. Capacidad de Pago | B6: =9+10+10 -> 29 | D6: 3.3 Sostenibilidad | E6: =8+8+8 -> 24
A7: 4. Colateral | B7: =7+7+7 -> 21 | D7: 3.4 Nivel de endeudamiento | E7: =9+8+9 -> 26
A8: 5. Condiciones de mercado | B8: =8+7+7 -> 22 | D8: 3.5 Medios de producción | E8: =8+6+6 -> 20
A9: PUNTAJE TOTAL SOBRE 100 | B9: =SUM(B4:B8) -> 122 | D9: 3.6 Razon Corriente | E9: =9+8+8 -> 25
D10: 3.7 Reprocidad de depòsitos | E10: =7+6+6 -> 19
A11: PARAMETROS DE CALIFICACION PARA CARACTER | E11: =SUM(E4:E10) -> 169
B12: Valorar sobre 10
A13: 1.1 Experiencia crediticia | B13: =10+9+10 -> 29 | D13: PARAMETROS DE CALIFICACION PARA COLATERAL
A14: 1.2 Arraigo del negocio | B14: =7+7+7 -> 21 | E14: Valorar sobre 10
A15: 1.3 Calidad de referencias | B15: =6+5+6 -> 17 | D15: 4.1 GARANTIA REAL
A16: 1.4 Calificación Interna | B16: =10+10+9 -> 29 | D16: 4.1.1 Comercialización | E16: 10
A17: 1.5 Arraigo Residencial | B17: =6+8+7 -> 21 | D17: 4.1.2 Estado | E17: 10
A18: 1.6 Estado Civil | B18: =5+5+5 -> 15 | D18: 4.1.3 Movilización | E18: 9
A19: 1.7 Genero | B19: =5+4+4 -> 13 | D19: 4.1.4 Calidad edif. Adyacentes | E19: 8
A20: 1.8 Datos Generales bàsicos | B20: 21 | D20: 4.1.5 Servicios Básicos | E20: 9
A21: PUNTAJE TOTAL SOBRE 100 | B21: =SUM(B13:B20) -> 166 | D21: 4.1.6 Avalúo | E21: 10
E22: =SUM(E16:E21) -> 56
A23: PARAMETROS DE CALIFICACION PARA CAPACIDAD DE GESTION | D23: 4.2 GARANTIA PERSONAL
B24: Valorar sobre 10 | D24: 4.2.1 Historial Credicitio | E24: 10
A25: 2.1 Experiencia en la actividad | B25: =10+8+9 -> 27 | D25: 4.2.2 Capacidad de Pago | E25: 10
A26: 2.2 Organización del negocio | B26: =8+8+8 -> 24 | D26: 4.2.3 Patrimonio | E26: 9
A27: 2.3 Dependencia de clientes | B27: =9+8+8 -> 25 | D27: 4.2.4 Documentos de respaldo | E27: 10
A28: 2.4 Dependencia de proveedores | B28: =7+7+7 -> 21 | E28: =SUM(E24:E27) -> 39
A29: 2.5 Dependencia del personal | B29: =7+6+7 -> 20
A30: 2.6 Dependencia de la actividad del socio | B30: =8+8+8 -> 24 | D30: PARAMETROS DE CALIFICACION PARA CONDICIONES DE MERCADO
A31: 2.7 Capacidad Administrativa (Educación) | B31: =7+8+7 -> 22 | E31: Valorar sobre 10
A32: 2.8 Local del negocio (SECTOR RURAL) (SECTOR URBANO) | B32: =8+6+7 -> 21 | D32: 5.1 Nivel de competencia | E32: =9+9+9 -> 27
B33: =SUM(B25:B32) -> 184 | D33: 5.2 Dinámica del sector | E33: =9+7+8 -> 24
D34: 5.3 Aceptación del producto | E34: =10+8+8 -> 26
E35: =SUM(E32:E34) -> 77
A41: 1. CARÁCTER | D41: 2. CAPACIDAD DE GESTION | G41: 3. CAPACIDAD DE PAGO | J41: 4. COLATERAL | M41: 5. CONDICIONES/MERCADO
A43: 1.1 Experiencia crediticia | D43: 2.1 Experiencia en la actividad | G43: 3.1 Capacidad de pago | J43: 4.1 GARANTIA REAL | M43: 5.1 Nivel de competencia
A44: 1 Puntual | B44: 4 | D44: 1 Más de 5 años | E44: 3.5 | G44: 1 Suficiente capacidad, cubre la cuota con exceso | J44: Comercialización: | M44: 1 Sin competencia en el medio | N44: 3
A45: 2 Atrazado | B45: 2 | D45: 2 Entre 3 y 5 años | E45: 2.5 | G45: sobre el 30%; ingresos provienen del negocio | H45: 20 | J45: 1 Corto Plazo | K45: 4 | M45: 2 Mediana competencia | N45: 2
A46: 3 Moroso | B46: 1 | D46: 3 Entre 1 y 3 años | E46: 1.5 | G46: 2 Buena capacidad, cubre la cuota con exceso de hasta | J46: 2 Mediano | K46: 2 | M46: 3 Alta competencia | N46: 1
A47: 4 Juicio o Castigado | B47: -20 | D47: 4 Menos de 1 año | E47: -40 | G47: el 29%, necesita otra fuente de ingresos | H47: 10 | J47: 3 Largo Plazo | K47: 0
...

Sheet DETALLE DE CALIFICACIONES
A2: PARAMETROS DE CALIFICACION DE RIESGO
A4: 1. Carácter | B4: =+'ENTRADA DE PARAMETROS'!B4 -> 29 | C4: =(B4/$B$9)*100 -> 23.770492
A5: 2. Capacidad de Gestión | B5: =+'ENTRADA DE PARAMETROS'!B5 -> 21 | C5: =(B5/$B$9)*100 -> 17.213115
A6: 3. Capacidad de Pago | B6: =+'ENTRADA DE PARAMETROS'!B6 -> 29 | C6: =(B6/$B$9)*100 -> 23.770492
A7: 4. Colateral | B7: =+'ENTRADA DE PARAMETROS'!B7 -> 21 | C7: =(B7/$B$9)*100 -> 17.213115
A8: 5. Condiciones de mercado | B8: =+'ENTRADA DE PARAMETROS'!B8 -> 22 | C8: =(B8/$B$9)*100 -> 18.032787
A9: PUNTAJE TOTAL SOBRE 100 | B9: =SUM(B4:B8) -> 122 | C9: =SUM(C4:C8) -> 100
A12: PARAMETROS DE CALIFICACION PARA CARACTER
A14: 1.1 Experiencia crediticia | B14: =+'ENTRADA DE PARAMETROS'!B13 -> 29 | C14: =+B14/$B$22 -> 0.1746988 | D14: =+C14*$D$22 -> 4.1526763
A15: 1.2 Arraigo del negocio | B15: =+'ENTRADA DE PARAMETROS'!B14 -> 21 | C15: =+B15/$B$22 -> 0.12650602 | D15: =+C15*$D$22 -> 3.0071104
A16: 1.3 Calidad de referencias | B16: =+'ENTRADA DE PARAMETROS'!B15 -> 17 | C16: =+B16/$B$22 -> 0.10240964 | D16: =+C16*$D$22 -> 2.4343275
A17: 1.4 Calificación Interna | B17: =+'ENTRADA DE PARAMETROS'!B16 -> 29 | C17: =+B17/$B$22 -> 0.1746988 | D17: =+C17*$D$22 -> 4.1526763
A18: 1.5 Arraigo Residencial | B18: =+'ENTRADA DE PARAMETROS'!B17 -> 21 | C18: =+B18/$B$22 -> 0.12650602 | D18: =+C18*$D$22 -> 3.0071104
A19: 1.6 Estado Civil | B19: =+'ENTRADA DE PARAMETROS'!B18 -> 15 | C19: =+B19/$B$22 -> 0.090361446 | D19: =+C19*$D$22 -> 2.147936
A20: 1.7 Genero | B20: =+'ENTRADA DE PARAMETROS'!B19 -> 13 | C20: =+B20/$B$22 -> 0.078313253 | D20: =+C20*$D$22 -> 1.8615445
A21: 1.8 Datos Generales bàsicos | B21: =+'ENTRADA DE PARAMETROS'!B20 -> 21 | C21: =+B21/$B$22 -> 0.12650602 | D21: =+C21*$D$22 -> 3.0071104
B22: =SUM(B14:B21) -> 166 | C22: =SUM(C14:C21) -> 1 | D22: =+C4 -> 23.770492
A24: PARAMETROS DE CALIFICACION PARA CAPACIDAD DE GESTION
A26: 2.1 Experiencia en la actividad | B26: =+'ENTRADA DE PARAMETROS'!B25 -> 27 | C26: =+B26/$B$34 -> 0.14673913 | D26: =+C26*$D$34 -> 2.5258375
A27: 2.2 Organización del negocio | B27: =+'ENTRADA DE PARAMETROS'!B26 -> 24 | C27: =+B27/$B$34 -> 0.13043478 | D27: =+C27*$D$34 -> 2.2451889
A28: 2.3 Dependencia de clientes | B28: =+'ENTRADA DE PARAMETROS'!B27 -> 25 | C28: =+B28/$B$34 -> 0.13586957 | D28: =+C28*$D$34 -> 2.3387384
A29: 2.4 Dependencia de proveedores | B29: =+'ENTRADA DE PARAMETROS'!B28 -> 21 | C29: =+B29/$B$34 -> 0.11413043 | D29: =+C29*$D$34 -> 1.9645403
A30: 2.5 Dependencia del personal | B30: =+'ENTRADA DE PARAMETROS'!B29 -> 20 | C30: =+B30/$B$34 -> 0.10869565 | D30: =+C30*$D$34 -> 1.8709907
A31: 2.6 Dependencia de la actividad del socio | B31: =+'ENTRADA DE PARAMETROS'!B30 -> 24 | C31: =+B31/$B$34 -> 0.13043478 | D31: =+C31*$D$34 -> 2.2451889
A32: 2.7 Capacidad Administrativa (Educación) | B32: =+'ENTRADA DE PARAMETROS'!B31 -> 22 | C32: =+B32/$B$34 -> 0.11956522 | D32: =+C32*$D$34 -> 2.0580898
A33: 2.8 Local del negocio (SECTOR RURAL) (SECTOR URBANO) | B33: =+'ENTRADA DE PARAMETROS'!B32 -> 21 | C33: =+B33/$B$34 -> 0.11413043 | D33: =+C33*$D$34 -> 1.9645403
B34: =SUM(B26:B33) -> 184 | C34: =SUM(C26:C33) -> 1 | D34: =+C5 -> 17.213115
A36: PARAMETROS DE CALIFICACION PARA CAPACIDAD DE PAGO
A38: 3.1 Capacidad de pago | B38: =+'ENTRADA DE PARAMETROS'!E4 -> 30 | C38: =+B38/$B$45 -> 0.17751479 | D38: =+C38*$D$45 -> 4.2196139
A39: 3.2 Rentabilidad sobre Capital | B39: =+'ENTRADA DE PARAMETROS'!E5 -> 25 | C39: =+B39/$B$45 -> 0.14792899 | D39: =+C39*$D$45 -> 3.5163449
A40: 3.3 Sostenibilidad | B40: =+'ENTRADA DE PARAMETROS'!E6 -> 24 | C40: =+B40/$B$45 -> 0.14201183 | D40: =+C40*$D$45 -> 3.3756911
A41: 3.4 Nivel de endeudamiento | B41: =+'ENTRADA DE PARAMETROS'!E7 -> 26 | C41: =+B41/$B$45 -> 0.15384615 | D41: =+C41*$D$45 -> 3.6569987
A42: 3.5 Medios de producción | B42: =+'ENTRADA DE PARAMETROS'!E8 -> 20 | C42: =+B42/$B$45 -> 0.1183432 | D42: =+C42*$D$45 -> 2.813076
A43: 3.6 Razon Corriente | B43: =+'ENTRADA DE PARAMETROS'!E9 -> 25 | C43: =+B43/$B$45 -> 0.14792899 | D43: =+C43*$D$45 -> 3.5163449
A44: 3.7 Reprocidad de depòsitos | B44: =+'ENTRADA DE PARAMETROS'!E10 -> 19 | C44: =+B44/$B$45 -> 0.11242604 | D44: =+C44*$D$45 -> 2.6724222
B45: =SUM(B38:B44) -> 169 | C45: =SUM(C38:C44) -> 1 | D45: =+C6 -> 23.770492
A47: PARAMETROS DE CALIFICACION PARA COLATERAL
F48: 4.3 GARANTIA MIXTA
A49: 4.1 GARANTIA REAL | F49: 4.1 GARANTIA REAL (59%)
A50: 4.1.1 Comercialización | B50: ='ENTRADA DE PARAMETROS'!E16 -> 10 | C50: =B50/$B$56 -> 0.17857143 | D50: =$D$56*C50 -> 3.0737705 | F50: 4.1.1 Comercialización | G50: 10 | H50: =G50/$G$65 -> 0.10526316 | I50: =H50*$I$65 -> 1.8273684
...

Sheet INGRESO DE DATOS
A1: CALIFICACION DE RIESGO DE CREDITO
A2: NUMERO DE SOCIO: | B2: ='Análisis Evaluación Crediticio'!B6:B7 -> #VALUE! | E2: ='Análisis Evaluación Crediticio'!C6 -> NAVAS PEÑAHERRERA GABRIEL HUMBERTO | F2: NOMBRE: | I2: Detalle el Sector (U = URBANO o R = RURAL) | K2: U | Q2: Detalle Garantía ( R=REAL P=PERSONAL Y SIN GARANTE M=MIXTO ) | S2: P | U2: L I S T A
U3: R | V3: REAL
A4: 1. CARÁCTER | B4: Cod | C4: Calif | E4: 2. CAPACIDAD DE GESTION | F4: Cod | G4: Calif. | I4: 3. CAPITAL | J4: Cod | K4: Calif | M4: 4. COLATERAL | N4: Cod | O4: Calif. | Q4: 5. CONDICIONES/MERCADO | R4: Cod | S4: Calif. | U4: P | V4: PERSONAL
U5: M | V5: MIXTA
A6: 1.1 Experiencia crediticia | B6: 1 | C6: =FORMULAS!E5 -> 4.1526763 | E6: 2.1 Experiencia en la actividad | F6: 1 | G6: =FORMULAS!J5 -> 2.5258375 | I6: 3.1 Capacidad de pago | J6: 1 | K6: =FORMULAS!O5 -> 4.2196139 | M6: 4.1 Garantia Real | Q6: 5.1 Nivel de competencia | R6: 2 | S6: =FORMULAS!Y5 -> 4.2154567
A7: 1 Puntual | E7: 1 Más de 5 años | I7: 1 Suficiente capacidad, cubre la | M7: Comercialización: | N7: 1 | O7: =FORMULAS!T6 -> 0 | Q7: 1 Sin competencia en el medio | U7: L I S T A
A8: 2 Atrazado | E8: 2 Entre 3 y 5 años | I8: cuota con exceso sobre el 30% | M8: 1 Corto Plazo | Q8: 2 Mediana competencia | U8: U | V8: URBANO
A9: 3 Moroso | E9: 3 Entre 1 y 3 años | I9: ingresos provienen del negocio | M9: 2 Mediano | Q9: 3 Alta competencia | U9: R | V9: RURAL
A10: 4 Juicio o Castigado | E10: 4 Menos de 1 año | F10: =IF(F6=4,"ALERTA","") | I10: 2 Buena capacidad, cubre la cuota | M10: 3 Largo Plazo | N10: =IF(N7=3,"MEJORAR GARANTIA","")
A11: 1.2 Arraigo del negocio | B11: 1 | C11: =FORMULAS!E11 -> 3.0071104 | E11: 2.2 Organización del negocio | F11: 2 | G11: =FORMULAS!J11 -> 1.6037063 | I11: con exceso de hasta el 29%, | J11: =IF(J6=3,"NEGADO","") | M11: Estado: | N11: 1 | O11: =FORMULAS!T11 -> 0 | Q11: 5.2 Dinámica del sector | R11: 2 | S11: =FORMULAS!Y10 -> 4.2154567
A12: 1 Más de 3 años | E12: 1 Buena organización, dispone de registros y | I12: necesita otra fuente de ingresos. | M12: 1 Optimo | Q12: 1 Sector en crecimiento.
A13: 2 Entre 2 y 3 años | E13: Dispone de registros y | I13: 3 Insuficiente capacidad, | M13: 2 Bueno | Q13: 2 Sector en estabilidad.
A14: 3 Entre 1 y 2 años | E14: sin problemas en la venta | I14: no cubre la cuota | M14: 3 Regular | Q14: 3 Sector estancado, sin proyecciones
A15: 4 Menos de 1 año | B15: =IF(B11=4,"ALERTA","") | E15: 2 Evidencia buen nivel de ventas | M15: Movilización: | N15: 1 | O15: =FORMULAS!T16 -> 0 | Q15: 4 Sector en recesión, decreciendo
A16: 1.3 Calidad de referencias | C16: =FORMULAS!E17 -> 2.4343275 | E16: pero con deficiencias | I16: 3.2 Rentabilidad sobre Capital | J16: 2 | K16: =FORMULAS!O12 -> 2.109807 | M16: 1 Buena
A17: Comerciales: | B17: 1 | E17: en la organización | I17: 1 Mayor en 3% a la inflación | M17: 2 Regular
A18: 1 Buena | E18: 3 Buena o aceptable organización | F18: =IF(F11=4,"ALERTA","") | I18: 2 Igual a la inflación | M18: 3 Deficiente | Q18: 5.3 Aceptación del producto | R18: 2 | S18: =FORMULAS!Y17 -> 3.0444965
A19: 2 Mala | E19: No posee registros | I19: 3 Menor que la inflación | M19: Calidad edif. adyacentes: | N19: 1 | O19: =FORMULAS!T21 -> 0 | Q19: 1 Alta aceptación por calidad/precio
A20: 3 No tiene referencias | B20: =IF(B17=3,"ALERTA","") | E20: con medianos problemas de venta | I20: 4 Pérdida | M20: 1 Buena | Q20: 2 Mediana aceptación
A21: Personales: | B21: 1 | E21: 4 Presenta mala organización | I21: 3.3 Sostenibilidad | J21: 2 | K21: =FORMULAS!O18 -> 1.6878456 | M21: 2 Regular | Q21: 3 Baja, dificultosa aceptación
A22: 1 Buena | E22: no dispone de registros | I22: 1 Relación Ingresos/gastos sobre 1,25 | M22: 3 Baja
A23: 2 Mala | E23: Con graves problemas en la venta | I23: 2 Relación Ingresos/gastos entre 1,10 y 1,25 | M23: Servicios Básicos: | N23: 1 | O23: =FORMULAS!T26 -> 0
A24: 3 No tiene referencias | B24: =IF(B21=3,"ALERTA","") | E24: 2.3 Dependencia de clientes | F24: 1 | G24: =FORMULAS!J21 -> 2.3387384 | I24: 3 Relación Ingresos/gastos menor a 1,10 | M24: 1 Todos | Q24: PUNTAJE CONDICIONES/MERCADO | S24: =SUM(S6:S21) -> 11.47541
A25: 1.4 Calificacion Interna | C25: =FORMULAS!E28 -> 4.1526763 | E25: 1 Sin importancia/consumo masivo | I25: 3.4 Nivel de endeudamiento | J25: 1 | K25: =FORMULAS!O23 -> 3.6569987 | M25: 2 Algunos
B26: 1 | E26: 2 Entre 4 y 8 compradores | I26: Relación Pasivos/Activos | M26: 3 Ninguno
A27: 1 Cliente A | E27: 3 Intermediario (entre 1 y 3 compradores) | F27: =IF(F24=3,"ALERTA","") | I27: 1 Menor al 30% | M27: Avalúo: | N27: 1 | O27: =FORMULAS!T31 -> 0 | Q27: RESUMEN CALIFICACION DE RIESGO
A28: 2 Cliente B | E28: 2.4 Dependencia de proveedores | F28: 2 | G28: =FORMULAS!J26 -> 1.4734052 | I28: 2 Entre 30% al 40% | M28: 1 Más del 200%
A29: 3 Cliente C | B29: =IF(B26=3,"NEGADO","") | E29: 1 Sin importancia/facilidad para proveerse | I29: 3 Entre 40% y 50% | M29: 2 El 200% | R29: Calif. Obtenida | S29: Calif. Optima
A30: 4 Clente D o E | B30: =IF(B26=4,"NEGADO","") | E30: 2 Más de 3 proveedores | I30: 4 Más del 50% | J30: =IF(J25=4,"NEGADO","") | M30: 3 Menos del 200% | Q30: Carácter | R30: =C54 -> 23.612976 | S30: ='DETALLE DE CALIFICACIONES'!C4 -> 23.770492
A31: 5 Cuentas cerradas | B31: =IF(B26=5,"ALERTA","") | E31: 3 Entre 2 a 3 proveedores | I31: 3.5 Medios de producción | J31: 1 | K31: =FORMULAS!O30 -> 2.813076 | Q31: Capacidad de Gestión | R31: =G57 -> 16.080497 | S31: ='DETALLE DE CALIFICACIONES'!C5 -> 17.213115
A32: 6 No tienereferencias | E32: 4 Un proveedor, alta dependencia | F32: =IF(F28=4,"ALERTA","") | I32: 1 Propietario del negocio o terreno | Q32: Capital | R32: =K46 -> 18.460811 | S32: ='DETALLE DE CALIFICACIONES'!C6 -> 23.770492
A33: 1.5 Arraigo Residencial | B33: 4 | C33: =FORMULAS!E37 -> 1.2028442 | E33: 2.5 Dependencia del personal | F33: 1 | G33: =FORMULAS!J32 -> 1.8709907 | I33: 2 En sociedad (al partir) | M33: 4.2 Garantia Personal y Sin Garante | Q33: Colateral | R33: =O55 -> 17.213115 | S33: ='DETALLE DE CALIFICACIONES'!C7 -> 17.213115
A34: 1 Propio | E34: 1 Familiar | I34: 3 Negocio o terreno arrendado | M34: Historial Credicitio: | N34: 1 | O34: =FORMULAS!T38 -> 4.4136192 | Q34: Condiciones de mercado | R34: =S24 -> 11.47541 | S34: ='DETALLE DE CALIFICACIONES'!C8 -> 18.032787
A35: 2 Más de 3 años | E35: 2 Familiar y trabajadores | I35: 3.6 Razon Corriente | J35: 2 | K35: =FORMULAS!O35 -> 2.6372587 | M35: 1 Pagos puntuales. Primer crédito
A36: 3 Entre 2 y 3 años | E36: 3 Sólo trabajadores | I36: 1 Màs del 200% | M36: 2 Atrasado | Q36: PUNTAJE TOTAL SOBRE 100 | R36: =SUM(R30:R34) -> 86.842809 | S36: =SUM(S30:S35) -> 100
A37: 4 Entre 1 y 2 años | E37: 2.6 Dependencia de la actividad del socio (RURAL) | F37: 1 | G37: =FORMULAS!J37 -> 2.2451889 | I37: 2 Del 200% al 175% | M37: 3 Moroso
A38: 5 Menos de 1 año | B38: =IF(B33=5,"ALERTA","") | E38: 1 Dos actividades o más | I38: 3 Del 175% al 150% | M38: 4 Juicio o castigado | Q38: Nivel de riesgo
A39: 6 No residente | B39: =IF(B33=6,"NEGADO","") | E39: 2 Dependencia de 1 sola actividad | I39: 4 Menor a 150% | M39: Capacidad de Pago: | N39: 1 | O39: =FORMULAS!T44 -> 4.4136192
A40: 1.6 Estado Civil | B40: 5 | C40: =FORMULAS!E45 -> 1.073968 | I40: 3.7 Reprocidad de depòsitos | J40: 2 | K40: =FORMULAS!O41 -> 1.3362111 | M40: 1 Suficiente | Q40: Bajo mayor o igual a 85 | R40: =IF(R36>=85,"APROBADO","") -> APROBADO
...

Sheet FECHAS DE ACTUALIZACI{ON
A1: FECHA | B1: MOTIVO
A2: 44685 | B2: INCREMENTO DE OFICIALES DE NEGOCIOS
A3: 44708 | B3: INCREMENTO DE OFICIALES DE NEGOCIOS

Sheet FORMULAS
A1: N° socio | F1: Detalle el Sector ( U = URBANO o R = RURAL ) | G1: ='INGRESO DE DATOS'!K2 -> U | P1: Detalle Garantía ( R=REAL P=PERSONAL M=MIXTO ) | R1: ='INGRESO DE DATOS'!S2 -> P
A2: N° solicitud
A3: ='ENTRADA DE PARAMETROS'!A41 -> 1. CARÁCTER | E3: ='DETALLE DE CALIFICACIONES'!C4 -> 23.770492 | F3: ='ENTRADA DE PARAMETROS'!D41 -> 2. CAPACIDAD DE GESTION | J3: ='DETALLE DE CALIFICACIONES'!C5 -> 17.213115 | K3: ='ENTRADA DE PARAMETROS'!G41 -> 3. CAPACIDAD DE PAGO | O3: ='DETALLE DE CALIFICACIONES'!C6 -> 23.770492 | P3: ='ENTRADA DE PARAMETROS'!J41 -> 4. COLATERAL | T3: ='DETALLE DE CALIFICACIONES'!C7 -> 17.213115 | U3: ='ENTRADA DE PARAMETROS'!M41 -> 5. CONDICIONES/MERCADO | Y3: ='DETALLE DE CALIFICACIONES'!C8 -> 18.032787
B4: Parámetros | C4: Calificación | D4: % | E4: Total | G4: Parámetros | H4: Calificación | I4: % | J4: Total | L4: Parámetros | M4: Calificación | N4: % | O4: Total | Q4: Parámetros | R4: Calificación | S4: % | T4: Total | V4: Parámetros | W4: Calificación | X4: % | Y4: Total
A5: ='ENTRADA DE PARAMETROS'!A43 -> 1.1 Experiencia crediticia | D5: ='DETALLE DE CALIFICACIONES'!C14 -> 0.1746988 | E5: =C10 -> 4.1526763 | F5: ='ENTRADA DE PARAMETROS'!D43 -> 2.1 Experiencia en la actividad | I5: ='DETALLE DE CALIFICACIONES'!C26 -> 0.14673913 | J5: =H10 -> 2.5258375 | K5: ='ENTRADA DE PARAMETROS'!G43 -> 3.1 Capacidad de pago | N5: ='DETALLE DE CALIFICACIONES'!C38 -> 0.17751479 | O5: =M11 -> 4.2196139 | P5: ='ENTRADA DE PARAMETROS'!J43 -> 4.1 GARANTIA REAL | U5: ='ENTRADA DE PARAMETROS'!M43 -> 5.1 Nivel de competencia | X5: ='DETALLE DE CALIFICACIONES'!C68 -> 0.35064935 | Y5: =W9 -> 4.2154567
A6: ='ENTRADA DE PARAMETROS'!A44 -> 1 Puntual | B6: ='ENTRADA DE PARAMETROS'!B44 -> 4 | C6: =IF('INGRESO DE DATOS'!$B$6=1,FORMULAS!B6/$B$6*$D$5*$E$3,0) -> 4.1526763 | F6: ='ENTRADA DE PARAMETROS'!D44 -> 1 Más de 5 años | G6: ='ENTRADA DE PARAMETROS'!E44 -> 3.5 | H6: =IF('INGRESO DE DATOS'!$F$6=1,FORMULAS!G6/FORMULAS!$G$6*FORMULAS!$I$5*FORMULAS!$J$3,0) -> 2.5258375 | K6: ='ENTRADA DE PARAMETROS'!G44 -> 1 Suficiente capacidad, cubre la cuota con exceso | P6: ='ENTRADA DE PARAMETROS'!J44 -> Comercialización: | S6: ='DETALLE DE CALIFICACIONES'!C50 -> 0.17857143 | T6: =IF($R$1="R",R10,IF($R$1="M",(R10*0.59),0)) -> 0 | U6: ='ENTRADA DE PARAMETROS'!M44 -> 1 Sin competencia en el medio | V6: ='ENTRADA DE PARAMETROS'!N44 -> 3 | W6: =IF('INGRESO DE DATOS'!$R$6=1,V6/$V$6*$X$5*$Y$3,0) -> 0
A7: ='ENTRADA DE PARAMETROS'!A45 -> 2 Atrazado | B7: ='ENTRADA DE PARAMETROS'!B45 -> 2 | C7: =IF('INGRESO DE DATOS'!$B$6=2,FORMULAS!B7/$B$6*$D$5*$E$3,0) -> 0 | F7: ='ENTRADA DE PARAMETROS'!D45 -> 2 Entre 3 y 5 años | G7: ='ENTRADA DE PARAMETROS'!E45 -> 2.5 | H7: =IF('INGRESO DE DATOS'!$F$6=2,FORMULAS!G7/FORMULAS!$G$6*FORMULAS!$I$5*FORMULAS!$J$3,0) -> 0 | K7: ='ENTRADA DE PARAMETROS'!G45 -> sobre el 30%; ingresos provienen del negocio | L7: ='ENTRADA DE PARAMETROS'!H45 -> 20 | M7: =IF('INGRESO DE DATOS'!$J$6=1,L7/$L$7*$N$5*$O$3,0) -> 4.2196139 | P7: ='ENTRADA DE PARAMETROS'!J45 -> 1 Corto Plazo | Q7: ='ENTRADA DE PARAMETROS'!K45 -> 4 | R7: =IF('INGRESO DE DATOS'!$N$7=1,Q7/$Q$7*$S$6*$T$3,0) -> 3.0737705 | U7: ='ENTRADA DE PARAMETROS'!M45 -> 2 Mediana competencia | V7: ='ENTRADA DE PARAMETROS'!N45 -> 2 | W7: =IF('INGRESO DE DATOS'!$R$6=2,V7/$V$6*$X$5*$Y$3,0) -> 4.2154567
A8: ='ENTRADA DE PARAMETROS'!A46 -> 3 Moroso | B8: ='ENTRADA DE PARAMETROS'!B46 -> 1 | C8: =IF('INGRESO DE DATOS'!$B$6=3,FORMULAS!B8/$B$6*$D$5*$E$3,0) -> 0 | F8: ='ENTRADA DE PARAMETROS'!D46 -> 3 Entre 1 y 3 años | G8: ='ENTRADA DE PARAMETROS'!E46 -> 1.5 | H8: =IF('INGRESO DE DATOS'!$F$6=3,FORMULAS!G8/FORMULAS!$G$6*FORMULAS!$I$5*FORMULAS!$J$3,0) -> 0 | K8: ='ENTRADA DE PARAMETROS'!G46 -> 2 Buena capacidad, cubre la cuota con exceso de hasta | P8: ='ENTRADA DE PARAMETROS'!J46 -> 2 Mediano | Q8: ='ENTRADA DE PARAMETROS'!K46 -> 2 | R8: =IF('INGRESO DE DATOS'!$N$7=2,Q8/$Q$7*$S$6*$T$3,0) -> 0 | U8: ='ENTRADA DE PARAMETROS'!M46 -> 3 Alta competencia | V8: ='ENTRADA DE PARAMETROS'!N46 -> 1 | W8: =IF('INGRESO DE DATOS'!$R$6=3,V8/$V$6*$X$5*$Y$3,0) -> 0
A9: ='ENTRADA DE PARAMETROS'!A47 -> 4 Juicio o Castigado | B9: ='ENTRADA DE PARAMETROS'!B47 -> -20 | C9: =IF('INGRESO DE DATOS'!$B$6=4,FORMULAS!B9/$B$6*$D$5*$E$3,0) -> 0 | F9: ='ENTRADA DE PARAMETROS'!D47 -> 4 Menos de 1 año | G9: ='ENTRADA DE PARAMETROS'!E47 -> -40 | H9: =IF('INGRESO DE DATOS'!$F$6=4,FORMULAS!G9/FORMULAS!$G$6*FORMULAS!$I$5*FORMULAS!$J$3,0) -> 0 | K9: ='ENTRADA DE PARAMETROS'!G47 -> el 29%, necesita otra fuente de ingresos | L9: ='ENTRADA DE PARAMETROS'!H47 -> 10 | M9: =IF('INGRESO DE DATOS'!$J$6=2,L9/$L$7*$N$5*$O$3,0) -> 0 | P9: ='ENTRADA DE PARAMETROS'!J47 -> 3 Largo Plazo | Q9: ='ENTRADA DE PARAMETROS'!K47 -> 0 | R9: =IF('INGRESO DE DATOS'!$N$7=3,Q9/$Q$7*$S$6*$T$3,0) -> 0 | W9: =SUM(W6:W8) -> 4.2154567
C10: =SUM(C6:C9) -> 4.1526763 | H10: =SUM(H6:H9) -> 2.5258375 | K10: ='ENTRADA DE PARAMETROS'!G48 -> 3 Insuficiente capacidad, no cubre la cuota. | L10: ='ENTRADA DE PARAMETROS'!H48 -> -40 | M10: =IF('INGRESO DE DATOS'!$J$6=3,L10/$L$7*$N$5*$O$3,0) -> 0 | R10: =SUM(R7:R9) -> 3.0737705 | U10: ='ENTRADA DE PARAMETROS'!M48 -> 5.2 Dinámica del sector | X10: ='DETALLE DE CALIFICACIONES'!C69 -> 0.31168831 | Y10: =W15 -> 4.2154567
A11: ='ENTRADA DE PARAMETROS'!A49 -> 1.2 Arraigo del negocio | D11: ='DETALLE DE CALIFICACIONES'!C15 -> 0.12650602 | E11: =C16 -> 3.0071104 | F11: ='ENTRADA DE PARAMETROS'!D49 -> 2.2 Organización del negocio | I11: ='DETALLE DE CALIFICACIONES'!C27 -> 0.13043478 | J11: =H20 -> 1.6037063 | M11: =SUM(M7:M10) -> 4.2196139 | P11: ='ENTRADA DE PARAMETROS'!J49 -> Estado: | S11: ='DETALLE DE CALIFICACIONES'!C51 -> 0.17857143 | T11: =IF($R$1="R",R15,IF($R$1="M",(R15*0.59),0)) -> 0 | U11: ='ENTRADA DE PARAMETROS'!M49 -> 1 Sector en crecimiento. | V11: ='ENTRADA DE PARAMETROS'!N49 -> 4 | W11: =IF('INGRESO DE DATOS'!$R$11=1,V11/$V$11*$X$10*$Y$3,0) -> 0
A12: ='ENTRADA DE PARAMETROS'!A50 -> 1 Más de 3 años | B12: ='ENTRADA DE PARAMETROS'!B50 -> 3 | C12: =IF('INGRESO DE DATOS'!$B$11=1,FORMULAS!B12/$B$12*$D$11*$E$3,0) -> 3.0071104 | F12: ='ENTRADA DE PARAMETROS'!D50 -> 1 Buena organización, dispone de registros y | K12: ='ENTRADA DE PARAMETROS'!G50 -> 3.2 Rentabilidad sobre Capital | N12: ='DETALLE DE CALIFICACIONES'!C39 -> 0.14792899 | O12: =M17 -> 2.109807 | P12: ='ENTRADA DE PARAMETROS'!J50 -> 1 Optimo | Q12: ='ENTRADA DE PARAMETROS'!K50 -> 4 | R12: =IF('INGRESO DE DATOS'!$N$11=1,Q12/$Q$12*$S$11*$T$3,0) -> 3.0737705 | U12: ='ENTRADA DE PARAMETROS'!M50 -> 2 Sector en estabilidad. | V12: ='ENTRADA DE PARAMETROS'!N50 -> 3 | W12: =IF('INGRESO DE DATOS'!$R$11=2,V12/$V$11*$X$10*$Y$3,0) -> 4.2154567
A13: ='ENTRADA DE PARAMETROS'!A51 -> 2 Entre 2 y 3 años | B13: ='ENTRADA DE PARAMETROS'!B51 -> 2 | C13: =IF('INGRESO DE DATOS'!$B$11=2,FORMULAS!B13/$B$12*$D$11*$E$3,0) -> 0 | F13: ='ENTRADA DE PARAMETROS'!D51 -> sin problemas en la venta | G13: ='ENTRADA DE PARAMETROS'!E51 -> 1.75 | H13: =IF('INGRESO DE DATOS'!$F$11=1,FORMULAS!G13/FORMULAS!$G$13*FORMULAS!$I$11*FORMULAS!$J$3,0) -> 0 | K13: ='ENTRADA DE PARAMETROS'!G51 -> 1 Mayor en 3% a la inflación | L13: ='ENTRADA DE PARAMETROS'!H51 -> 2.5 | M13: =IF('INGRESO DE DATOS'!$J$16=1,L13/$L$13*$N$12*$O$3,0) -> 0 | P13: ='ENTRADA DE PARAMETROS'!J51 -> 2 Bueno | Q13: ='ENTRADA DE PARAMETROS'!K51 -> 3 | R13: =IF('INGRESO DE DATOS'!$N$11=2,Q13/$Q$12*$S$11*$T$3,0) -> 0 | U13: ='ENTRADA DE PARAMETROS'!M51 -> 3 Sector estancado, sin proyecciones | V13: ='ENTRADA DE PARAMETROS'!N51 -> 2 | W13: =IF('INGRESO DE DATOS'!$R$11=3,V13/$V$11*$X$10*$Y$3,0) -> 0
A14: ='ENTRADA DE PARAMETROS'!A52 -> 3 Entre 1 y 2 años | B14: ='ENTRADA DE PARAMETROS'!B52 -> 1 | C14: =IF('INGRESO DE DATOS'!$B$11=3,FORMULAS!B14/$B$12*$D$11*$E$3,0) -> 0 | F14: ='ENTRADA DE PARAMETROS'!D52 -> 2 Evidencia buen nivel de ventas, pero con | K14: ='ENTRADA DE PARAMETROS'!G52 -> 2 Igual a la inflación | L14: ='ENTRADA DE PARAMETROS'!H52 -> 1.5 | M14: =IF('INGRESO DE DATOS'!$J$16=2,L14/$L$13*$N$12*$O$3,0) -> 2.109807 | P14: ='ENTRADA DE PARAMETROS'!J52 -> 3 Regular | Q14: ='ENTRADA DE PARAMETROS'!K52 -> 1 | R14: =IF('INGRESO DE DATOS'!$N$11=3,Q14/$Q$12*$S$11*$T$3,0) -> 0 | U14: ='ENTRADA DE PARAMETROS'!M52 -> 4 Sector en recesión, decreciendo | V14: ='ENTRADA DE PARAMETROS'!N52 -> 1 | W14: =IF('INGRESO DE DATOS'!$R$11=4,V14/$V$11*$X$10*$Y$3,0) -> 0
A15: ='ENTRADA DE PARAMETROS'!A53 -> 4 Menos de 1 año | B15: ='ENTRADA DE PARAMETROS'!B53 -> -10 | C15: =IF('INGRESO DE DATOS'!$B$11=4,FORMULAS!B15/$B$12*$D$11*$E$3,0) -> 0 | F15: ='ENTRADA DE PARAMETROS'!D53 -> deficiencias en la organización | G15: ='ENTRADA DE PARAMETROS'!E53 -> 1.25 | H15: =IF('INGRESO DE DATOS'!$F$11=2,FORMULAS!G15/FORMULAS!$G$13*FORMULAS!$I$11*FORMULAS!$J$3,0) -> 1.6037063 | K15: ='ENTRADA DE PARAMETROS'!G53 -> 3 Menor que la inflación | L15: ='ENTRADA DE PARAMETROS'!H53 -> 0 | M15: =IF('INGRESO DE DATOS'!$J$16=3,L15/$L$13*$N$12*$O$3,0) -> 0 | R15: =SUM(R12:R14) -> 3.0737705 | W15: =SUM(W11:W14) -> 4.2154567
C16: =SUM(C12:C15) -> 3.0071104 | F16: ='ENTRADA DE PARAMETROS'!D54 -> 3 Buena o aceptable organización, pero no | K16: ='ENTRADA DE PARAMETROS'!G54 -> 4 Pérdida | L16: ='ENTRADA DE PARAMETROS'!H54 -> -2 | M16: =IF('INGRESO DE DATOS'!$J$16=4,L16/$L$13*$N$12*$O$3,0) -> 0 | P16: ='ENTRADA DE PARAMETROS'!J54 -> Movilización: | S16: ='DETALLE DE CALIFICACIONES'!C52 -> 0.16071429 | T16: =IF($R$1="R",R20,IF($R$1="M",(R20*0.59),0)) -> 0
A17: ='ENTRADA DE PARAMETROS'!A55 -> 1.3 Calidad de referencias | D17: ='DETALLE DE CALIFICACIONES'!C16 -> 0.10240964 | E17: =C27 -> 2.4343275 | F17: ='ENTRADA DE PARAMETROS'!D55 -> posee registros y/o con medianos problemas de venta | G17: ='ENTRADA DE PARAMETROS'!E55 -> 0.75 | H17: =IF('INGRESO DE DATOS'!$F$11=3,FORMULAS!G17/FORMULAS!$G$13*FORMULAS!$I$11*FORMULAS!$J$3,0) -> 0 | M17: =SUM(M13:M16) -> 2.109807 | P17: ='ENTRADA DE PARAMETROS'!J55 -> 1 Buena | Q17: ='ENTRADA DE PARAMETROS'!K55 -> 4 | R17: =IF('INGRESO DE DATOS'!$N$15=1,Q17/$Q$17*$S$16*$T$3,0) -> 2.7663934 | U17: ='ENTRADA DE PARAMETROS'!M55 -> 5.3 Aceptación del producto | X17: ='DETALLE DE CALIFICACIONES'!C70 -> 0.33766234 | Y17: =W21 -> 3.0444965
A18: ='ENTRADA DE PARAMETROS'!A56 -> Comerciales: | F18: ='ENTRADA DE PARAMETROS'!D56 -> 4 Presenta mala organización, no dispone | K18: ='ENTRADA DE PARAMETROS'!G56 -> 3.3 Sostenibilidad | N18: ='DETALLE DE CALIFICACIONES'!C40 -> 0.14201183 | O18: =M22 -> 1.6878456 | P18: ='ENTRADA DE PARAMETROS'!J56 -> 2 Regular | Q18: ='ENTRADA DE PARAMETROS'!K56 -> 3 | R18: =IF('INGRESO DE DATOS'!$N$15=2,Q18/$Q$17*$S$16*$T$3,0) -> 0 | U18: ='ENTRADA DE PARAMETROS'!M56 -> 1 Alta aceptación por calidad/precio | V18: ='ENTRADA DE PARAMETROS'!N56 -> 4 | W18: =IF('INGRESO DE DATOS'!$R$18=1,V18/$V$18*$X$17*$Y$3,0) -> 0
A19: ='ENTRADA DE PARAMETROS'!A57 -> 1 Buena | B19: ='ENTRADA DE PARAMETROS'!B57 -> 1 | C19: =IF('INGRESO DE DATOS'!$B$17=1,FORMULAS!B19/$B$19*($D$17*$E$3)/2,0) -> 1.2171637 | F19: ='ENTRADA DE PARAMETROS'!D57 -> de registros y/o con graves problemas en la venta | G19: ='ENTRADA DE PARAMETROS'!E57 -> 1 | H19: =IF('INGRESO DE DATOS'!$F$11=4,FORMULAS!G19/FORMULAS!$G$13*FORMULAS!$I$11*FORMULAS!$J$3,0) -> 0 | K19: ='ENTRADA DE PARAMETROS'!G57 -> 1 Relación Ingresos/gastos sobre 1,25 | L19: ='ENTRADA DE PARAMETROS'!H57 -> 4 | M19: =IF('INGRESO DE DATOS'!$J$21=1,L19/$L$19*$N$18*$O$3,0) -> 0 | P19: ='ENTRADA DE PARAMETROS'!J57 -> 3 Deficiente | Q19: ='ENTRADA DE PARAMETROS'!K57 -> 0 | R19: =IF('INGRESO DE DATOS'!$N$15=3,Q19/$Q$17*$S$16*$T$3,0) -> 0 | U19: ='ENTRADA DE PARAMETROS'!M57 -> 2 Mediana aceptación | V19: ='ENTRADA DE PARAMETROS'!N57 -> 2 | W19: =IF('INGRESO DE DATOS'!$R$18=2,V19/$V$18*$X$17*$Y$3,0) -> 3.0444965
A20: ='ENTRADA DE PARAMETROS'!A58 -> 2 Mala | B20: ='ENTRADA DE PARAMETROS'!B58 -> -1 | C20: =IF('INGRESO DE DATOS'!$B$17=2,FORMULAS!B20/$B$19*($D$17*$E$3)/2,0) -> 0 | H20: =SUM(H13:H19) -> 1.6037063 | K20: ='ENTRADA DE PARAMETROS'!G58 -> 2 Relación Ingresos/gastos entre 1,10 y 1,25 | L20: ='ENTRADA DE PARAMETROS'!H58 -> 2 | M20: =IF('INGRESO DE DATOS'!$J$21=2,L20/$L$19*$N$18*$O$3,0) -> 1.6878456 | R20: =SUM(R17:R19) -> 2.7663934 | U20: ='ENTRADA DE PARAMETROS'!M58 -> 3 Baja, dificultosa aceptación | V20: ='ENTRADA DE PARAMETROS'!N58 -> 0 | W20: =IF('INGRESO DE DATOS'!$R$18=3,V20/$V$18*$X$17*$Y$3,0) -> 0
A21: ='ENTRADA DE PARAMETROS'!A59 -> 3 No tiene referencias | B21: ='ENTRADA DE PARAMETROS'!B59 -> 0.2 | C21: =IF('INGRESO DE DATOS'!$B$17=3,FORMULAS!B21/$B$19*($D$17*$E$3)/2,0) -> 0 | F21: ='ENTRADA DE PARAMETROS'!D59 -> 2.3 Dependencia de clientes | I21: ='DETALLE DE CALIFICACIONES'!C28 -> 0.13586957 | J21: =H25 -> 2.3387384 | K21: ='ENTRADA DE PARAMETROS'!G59 -> 3 Relación Ingresos/gastos menor a 1,10 | L21: ='ENTRADA DE PARAMETROS'!H59 -> -20 | M21: =IF('INGRESO DE DATOS'!$J$21=3,L21/$L$19*$N$18*$O$3,0) -> 0 | P21: ='ENTRADA DE PARAMETROS'!J59 -> Calidad edif. adyacentes: | S21: ='DETALLE DE CALIFICACIONES'!C53 -> 0.14285714 | T21: =IF($R$1="R",R25,IF($R$1="M",(R25*0.59),0)) -> 0 | W21: =SUM(W18:W20) -> 3.0444965
F22: ='ENTRADA DE PARAMETROS'!D60 -> 1 Sin importancia/consumo masivo | G22: ='ENTRADA DE PARAMETROS'!E60 -> 1.75 | H22: =IF('INGRESO DE DATOS'!$F$24=1,FORMULAS!G22/FORMULAS!$G$22*FORMULAS!$I$21*FORMULAS!$J$3,0) -> 2.3387384 | M22: =SUM(M19:M21) -> 1.6878456 | P22: ='ENTRADA DE PARAMETROS'!J60 -> 1 Buena | Q22: ='ENTRADA DE PARAMETROS'!K60 -> 4 | R22: =IF('INGRESO DE DATOS'!$N$19=1,Q22/$Q$22*$S$21*$T$3,0) -> 2.4590164 | U22: PUNTAJE TOTAL | X22: =SUM(X5:X21) -> 1 | Y22: =SUM(Y5:Y21) -> 11.47541
A23: ='ENTRADA DE PARAMETROS'!A61 -> Personales: | F23: ='ENTRADA DE PARAMETROS'!D61 -> 2 Entre 4 y 8 compradores | G23: ='ENTRADA DE PARAMETROS'!E61 -> 1 | H23: =IF('INGRESO DE DATOS'!$F$24=2,FORMULAS!G23/FORMULAS!$G$22*FORMULAS!$I$21*FORMULAS!$J$3,0) -> 0 | K23: ='ENTRADA DE PARAMETROS'!G61 -> 3.4 Nivel de endeudamiento | N23: ='DETALLE DE CALIFICACIONES'!C41 -> 0.15384615 | O23: =M29 -> 3.6569987 | P23: ='ENTRADA DE PARAMETROS'!J61 -> 2 Regular | Q23: ='ENTRADA DE PARAMETROS'!K61 -> 3 | R23: =IF('INGRESO DE DATOS'!$N$19=2,Q23/$Q$22*$S$21*$T$3,0) -> 0
A24: ='ENTRADA DE PARAMETROS'!A62 -> 1 Buena | B24: ='ENTRADA DE PARAMETROS'!B62 -> 1 | C24: =IF('INGRESO DE DATOS'!$B$21=1,FORMULAS!B24/$B$24*($D$17*$E$3)/2,0) -> 1.2171637 | F24: ='ENTRADA DE PARAMETROS'!D62 -> 3 Intermediario (entre 1 y 3 compradores) | G24: ='ENTRADA DE PARAMETROS'!E62 -> 0 | H24: =IF('INGRESO DE DATOS'!$F$24=3,FORMULAS!G24/FORMULAS!$G$22*FORMULAS!$I$21*FORMULAS!$J$3,0) -> 0 | K24: ='ENTRADA DE PARAMETROS'!G62 -> Relación Pasivos/Activos | P24: ='ENTRADA DE PARAMETROS'!J62 -> 3 Baja | Q24: ='ENTRADA DE PARAMETROS'!K62 -> 0 | R24: =IF('INGRESO DE DATOS'!$N$19=3,Q24/$Q$22*$S$21*$T$3,0) -> 0
A25: ='ENTRADA DE PARAMETROS'!A63 -> 2 Mala | B25: ='ENTRADA DE PARAMETROS'!B63 -> -1 | C25: =IF('INGRESO DE DATOS'!$B$21=2,FORMULAS!B25/$B$24*($D$17*$E$3)/2,0) -> 0 | H25: =SUM(H22:H24) -> 2.3387384 | K25: ='ENTRADA DE PARAMETROS'!G63 -> 1 Menor al 30% | L25: ='ENTRADA DE PARAMETROS'!H63 -> 4 | M25: =IF('INGRESO DE DATOS'!$J$25=1,L25/$L$25*$N$23*$O$3,0) -> 3.6569987 | R25: =SUM(R22:R24) -> 2.4590164
A26: ='ENTRADA DE PARAMETROS'!A64 -> 3 No tiene referencias | B26: ='ENTRADA DE PARAMETROS'!B64 -> 0.2 | C26: =IF('INGRESO DE DATOS'!$B$21=3,FORMULAS!B26/$B$24*($D$17*$E$3)/2,0) -> 0 | F26: ='ENTRADA DE PARAMETROS'!D64 -> 2.4 Dependencia de proveedores | I26: ='DETALLE DE CALIFICACIONES'!C29 -> 0.11413043 | J26: =H31 -> 1.4734052 | K26: ='ENTRADA DE PARAMETROS'!G64 -> 2 Entre 30% al 40% | L26: ='ENTRADA DE PARAMETROS'!H64 -> 3 | M26: =IF('INGRESO DE DATOS'!$J$25=2,L26/$L$25*$N$23*$O$3,0) -> 0 | P26: ='ENTRADA DE PARAMETROS'!J64 -> Servicios Básicos: | S26: ='DETALLE DE CALIFICACIONES'!C54 -> 0.16071429 | T26: =IF($R$1="R",R30,IF($R$1="M",(R30*0.59),0)) -> 0
C27: =SUM(C19:C26) -> 2.4343275 | F27: ='ENTRADA DE PARAMETROS'!D65 -> 1 Sin importancia/facilidad para proveerse | G27: ='ENTRADA DE PARAMETROS'!E65 -> 1 | H27: =IF('INGRESO DE DATOS'!$F$28=1,FORMULAS!G27/FORMULAS!$G$27*FORMULAS!$I$26*FORMULAS!$J$3,0) -> 0 | K27: ='ENTRADA DE PARAMETROS'!G65 -> 3 Entre 40% y 50% | L27: ='ENTRADA DE PARAMETROS'!H65 -> 2 | M27: =IF('INGRESO DE DATOS'!$J$25=3,L27/$L$25*$N$23*$O$3,0) -> 0 | P27: ='ENTRADA DE PARAMETROS'!J65 -> 1 Todos | Q27: ='ENTRADA DE PARAMETROS'!K65 -> 4 | R27: =IF('INGRESO DE DATOS'!$N$23=1,Q27/$Q$27*$S$26*$T$3,0) -> 2.7663934
A28: ='ENTRADA DE PARAMETROS'!A66 -> 1.4 Calificación Interna | D28: ='DETALLE DE CALIFICACIONES'!C17 -> 0.1746988 | E28: =C36 -> 4.1526763 | F28: ='ENTRADA DE PARAMETROS'!D66 -> 2 Más de 3 proveedores | G28: ='ENTRADA DE PARAMETROS'!E66 -> 0.75 | H28: =IF('INGRESO DE DATOS'!$F$28=2,FORMULAS!G28/FORMULAS!$G$27*FORMULAS!$I$26*FORMULAS!$J$3,0) -> 1.4734052 | K28: ='ENTRADA DE PARAMETROS'!G66 -> 4 Más del 50% | L28: ='ENTRADA DE PARAMETROS'!H66 -> -20 | M28: =IF('INGRESO DE DATOS'!$J$25=4,L28/$L$25*$N$23*$O$3,0) -> 0 | P28: ='ENTRADA DE PARAMETROS'!J66 -> 2 Algunos | Q28: ='ENTRADA DE PARAMETROS'!K66 -> 3 | R28: =IF('INGRESO DE DATOS'!$N$23=2,Q28/$Q$27*$S$26*$T$3,0) -> 0
A29: ='ENTRADA DE PARAMETROS'!A67 -> Referencias bancarias | F29: ='ENTRADA DE PARAMETROS'!D67 -> 3 Entre 2 a 3 proveedores | G29: ='ENTRADA DE PARAMETROS'!E67 -> 0.5 | H29: =IF('INGRESO DE DATOS'!$F$28=3,FORMULAS!G29/FORMULAS!$G$27*FORMULAS!$I$26*FORMULAS!$J$3,0) -> 0 | M29: =SUM(M25:M28) -> 3.6569987 | P29: ='ENTRADA DE PARAMETROS'!J67 -> 3 Ninguno | Q29: ='ENTRADA DE PARAMETROS'!K67 -> 0 | R29: =IF('INGRESO DE DATOS'!$N$23=3,Q29/$Q$27*$S$26*$T$3,0) -> 0
A30: ='ENTRADA DE PARAMETROS'!A68 -> 1 Cliente A | B30: ='ENTRADA DE PARAMETROS'!B68 -> 6 | C30: =IF('INGRESO DE DATOS'!$B$26=1,FORMULAS!B30/$B$30*$D$28*$E$3,0) -> 4.1526763 | F30: ='ENTRADA DE PARAMETROS'!D68 -> 4 Un proveedor, alta dependencia | G30: ='ENTRADA DE PARAMETROS'!E68 -> 0 | H30: =IF('INGRESO DE DATOS'!$F$28=4,FORMULAS!G30/FORMULAS!$G$27*FORMULAS!$I$26*FORMULAS!$J$3,0) -> 0 | K30: ='ENTRADA DE PARAMETROS'!G68 -> 3.5 Medios de producción | N30: ='DETALLE DE CALIFICACIONES'!C42 -> 0.1183432 | O30: =M34 -> 2.813076 | R30: =SUM(R27:R29) -> 2.7663934
A31: ='ENTRADA DE PARAMETROS'!A69 -> 2 Cliente B | B31: ='ENTRADA DE PARAMETROS'!B69 -> 4 | C31: =IF('INGRESO DE DATOS'!$B$26=2,FORMULAS!B31/$B$30*$D$28*$E$3,0) -> 0 | H31: =SUM(H27:H30) -> 1.4734052 | K31: ='ENTRADA DE PARAMETROS'!G69 -> 1 Propietario del negocio o terreno | L31: ='ENTRADA DE PARAMETROS'!H69 -> 2.5 | M31: =IF('INGRESO DE DATOS'!$J$31=1,L31/$L$31*$N$30*$O$3,0) -> 2.813076 | P31: ='ENTRADA DE PARAMETROS'!J69 -> Avalúo: | S31: ='DETALLE DE CALIFICACIONES'!C55 -> 0.17857143 | T31: =IF($R$1="R",R35,IF($R$1="M",(R35*0.59),0)) -> 0
A32: ='ENTRADA DE PARAMETROS'!A70 -> 3 Cliente C | B32: ='ENTRADA DE PARAMETROS'!B70 -> -100 | C32: =IF('INGRESO DE DATOS'!$B$26=3,FORMULAS!B32/$B$30*$D$28*$E$3,0) -> 0 | F32: ='ENTRADA DE PARAMETROS'!D70 -> 2.5 Dependencia del personal | I32: ='DETALLE DE CALIFICACIONES'!C30 -> 0.10869565 | J32: =H36 -> 1.8709907 | K32: ='ENTRADA DE PARAMETROS'!G70 -> 2 En sociedad (al partir) | L32: ='ENTRADA DE PARAMETROS'!H70 -> 2 | M32: =IF('INGRESO DE DATOS'!$J$31=2,L32/$L$31*$N$30*$O$3,0) -> 0 | P32: ='ENTRADA DE PARAMETROS'!J70 -> 1 Más del 200% | Q32: ='ENTRADA DE PARAMETROS'!K70 -> 4 | R32: =IF('INGRESO DE DATOS'!$N$27=1,Q32/$Q$32*$S$31*$T$3,0) -> 3.0737705
A33: ='ENTRADA DE PARAMETROS'!A71 -> 4 Clente D o E | B33: ='ENTRADA DE PARAMETROS'!B71 -> -100 | C33: =IF('INGRESO DE DATOS'!$B$26=4,FORMULAS!B33/$B$30*$D$28*$E$3,0) -> 0 | F33: ='ENTRADA DE PARAMETROS'!D71 -> 1 Familiar | G33: ='ENTRADA DE PARAMETROS'!E71 -> 0.5 | H33: =IF('INGRESO DE DATOS'!$F$33=1,FORMULAS!G33/FORMULAS!$G$33*FORMULAS!$I$32*FORMULAS!$J$3,0) -> 1.8709907 | K33: ='ENTRADA DE PARAMETROS'!G71 -> 3 Negocio o terreno arrendado | L33: ='ENTRADA DE PARAMETROS'!H71 -> 1.5 | M33: =IF('INGRESO DE DATOS'!$J$31=3,L33/$L$31*$N$30*$O$3,0) -> 0 | P33: ='ENTRADA DE PARAMETROS'!J71 -> 2 El 200% | Q33: ='ENTRADA DE PARAMETROS'!K71 -> 2 | R33: =IF('INGRESO DE DATOS'!$N$27=2,Q33/$Q$32*$S$31*$T$3,0) -> 0
A34: ='ENTRADA DE PARAMETROS'!A72 -> 5 Cuentas cerradas | B34: ='ENTRADA DE PARAMETROS'!B72 -> -20 | C34: =IF('INGRESO DE DATOS'!$B$26=5,FORMULAS!B34/$B$30*$D$28*$E$3,0) -> 0 | F34: ='ENTRADA DE PARAMETROS'!D72 -> 2 Familiar y trabajadores | G34: ='ENTRADA DE PARAMETROS'!E72 -> 0.25 | H34: =IF('INGRESO DE DATOS'!$F$33=2,FORMULAS!G34/FORMULAS!$G$33*FORMULAS!$I$32*FORMULAS!$J$3,0) -> 0 | M34: =SUM(M31:M33) -> 2.813076 | P34: ='ENTRADA DE PARAMETROS'!J72 -> 3 Menos del 200% | Q34: ='ENTRADA DE PARAMETROS'!K72 -> -15 | R34: =IF('INGRESO DE DATOS'!$N$27=3,Q34/$Q$32*$S$31*$T$3,0) -> 0
A35: ='ENTRADA DE PARAMETROS'!A73 -> 6 No tienereferencias | B35: ='ENTRADA DE PARAMETROS'!B73 -> 1 | C35: =IF('INGRESO DE DATOS'!$B$26=6,FORMULAS!B35/$B$30*$D$28*$E$3,0) -> 0 | F35: ='ENTRADA DE PARAMETROS'!D73 -> 3 Sólo trabajadores | G35: ='ENTRADA DE PARAMETROS'!E73 -> 0 | H35: =IF('INGRESO DE DATOS'!$F$33=3,FORMULAS!G35/FORMULAS!$G$33*FORMULAS!$I$32*FORMULAS!$J$3,0) -> 0 | K35: ='ENTRADA DE PARAMETROS'!G73 -> 3.6 Razon Corriente | N35: ='DETALLE DE CALIFICACIONES'!C43 -> 0.14792899 | O35: =M40 -> 2.6372587 | R35: =SUM(R32:R34) -> 3.0737705
C36: =SUM(C30:C35) -> 4.1526763 | H36: =SUM(H33:H35) -> 1.8709907 | K36: ='ENTRADA DE PARAMETROS'!G74 -> 1 Màs del 200% | L36: ='ENTRADA DE PARAMETROS'!H74 -> 4 | M36: =IF('INGRESO DE DATOS'!$J$35=1,L36/$L$36*$N$35*$O$3,0) -> 0 | P36: PUNTAJE TOTAL | S36: =SUM(S5:S35) -> 1 | T36: =SUM(T5:T35) -> 0
A37: ='ENTRADA DE PARAMETROS'!A75 -> 1.5 Arraigo Residencial | D37: ='DETALLE DE CALIFICACIONES'!C18 -> 0.12650602 | E37: =C44 -> 1.2028442 | F37: ='ENTRADA DE PARAMETROS'!D75 -> 2.6 Dependencia de la actividad del socio (RURAL) | I37: ='DETALLE DE CALIFICACIONES'!C31 -> 0.13043478 | J37: =IF($G$1="R",H40,IF($G$1="U",H44,0)) -> 2.2451889 | K37: ='ENTRADA DE PARAMETROS'!G75 -> 2 Del 200% al 175% | L37: ='ENTRADA DE PARAMETROS'!H75 -> 3 | M37: =IF('INGRESO DE DATOS'!$J$35=2,L37/$L$36*$N$35*$O$3,0) -> 2.6372587 | P37: ='ENTRADA DE PARAMETROS'!J75 -> 4.2 Garantia Personal
A38: ='ENTRADA DE PARAMETROS'!A76 -> 1 Propio | B38: ='ENTRADA DE PARAMETROS'!B76 -> 5 | C38: =IF('INGRESO DE DATOS'!$B$33=1,FORMULAS!B38/$B$38*$D$37*$E$3,0) -> 0 | F38: ='ENTRADA DE PARAMETROS'!D76 -> 1 Dos actividades o más | G38: ='ENTRADA DE PARAMETROS'!E76 -> 3.5 | H38: =IF('INGRESO DE DATOS'!$F$37=1,FORMULAS!G38/FORMULAS!$G$38*FORMULAS!$I$37*FORMULAS!$J$3,0) -> 2.2451889 | K38: ='ENTRADA DE PARAMETROS'!G76 -> 3 Del 175% al 150% | L38: ='ENTRADA DE PARAMETROS'!H76 -> 2 | M38: =IF('INGRESO DE DATOS'!$J$35=3,L38/$L$36*$N$35*$O$3,0) -> 0 | P38: ='ENTRADA DE PARAMETROS'!J76 -> Historial Credicitio: | S38: ='DETALLE DE CALIFICACIONES'!C60 -> 0.25641026 | T38: =IF($R$1="P",R43,IF($R$1="M",(R43*0.41),0)) -> 4.4136192
A39: ='ENTRADA DE PARAMETROS'!A77 -> 2 Más de 3 años | B39: ='ENTRADA DE PARAMETROS'!B77 -> 4 | C39: =IF('INGRESO DE DATOS'!$B$33=2,FORMULAS!B39/$B$38*$D$37*$E$3,0) -> 0 | F39: ='ENTRADA DE PARAMETROS'!D77 -> 2 Dependencia de 1 sola actividad | G39: ='ENTRADA DE PARAMETROS'!E77 -> 1.5 | H39: =IF('INGRESO DE DATOS'!$F$37=2,FORMULAS!G39/FORMULAS!$G$38*FORMULAS!$I$37*FORMULAS!$J$3,0) -> 0 | K39: ='ENTRADA DE PARAMETROS'!G77 -> 4 Menor a 150% | L39: ='ENTRADA DE PARAMETROS'!H77 -> 0 | M39: =IF('INGRESO DE DATOS'!$J$35=4,L39/$L$36*$N$35*$O$3,0) -> 0 | P39: ='ENTRADA DE PARAMETROS'!J77 -> 1 Pagos puntuales. Primer crédito | Q39: ='ENTRADA DE PARAMETROS'!K77 -> 4 | R39: =IF('INGRESO DE DATOS'!$N$34=1,Q39/$Q$39*$S$38*$T$3,0) -> 4.4136192
A40: ='ENTRADA DE PARAMETROS'!A78 -> 3 Entre 2 y 3 años | B40: ='ENTRADA DE PARAMETROS'!B78 -> 3 | C40: =IF('INGRESO DE DATOS'!$B$33=3,FORMULAS!B40/$B$38*$D$37*$E$3,0) -> 0 | H40: =SUM(H38:H39) -> 2.2451889 | M40: =SUM(M36:M39) -> 2.6372587 | P40: ='ENTRADA DE PARAMETROS'!J78 -> 2 Atrasado | Q40: ='ENTRADA DE PARAMETROS'!K78 -> 1 | R40: =IF('INGRESO DE DATOS'!$N$34=2,Q40/$Q$39*$S$38*$T$3,0) -> 0
...

Sheet OFICIALES DE NEGOCIO
A3: Nº | B3: OFICINA | C3: CÓDIGO | D3: CÓDIGO OFICIAL DE NEG. | E3: NOMBRES Y APELLIDOS
A4: 1 | B4: TULCAN | C4: 1 | D4: 1-01 | E4: CHIRIBOGA VALENCIA SOFIA CAROLINA
A5: 2 | B5: TULCAN | C5: 1 | D5: 1-02 | E5: GUZMAN TATES JOHANA LICETH
A6: 3 | B6: TULCAN | C6: 1 | D6: 1-03 | E6: ENRIQUEZ MERA DARWIN JAVIER
A7: 4 | B7: TULCAN | C7: 1 | D7: 1-04 | E7: FUEL CHINGAL ANA KAREN
A8: 5 | B8: TULCAN | C8: 1 | D8: 1-05 | E8: ERAZO DEL CASTILLO DIANA MILENA
A9: 6 | B9: TULCAN | C9: 1 | D9: 1-06 | E9: DISPONIBLE
A10: 7 | B10: TULCAN | C10: 1 | D10: 1-07 | E10: FUENTES BOLAÑOS JENNIFFER JOHANNA
A11: 8 | B11: TULCAN | C11: 1 | D11: 1-08 | E11: QUIÑONEZ MONTERO MARGOTH KATHERINE
A12: 9 | B12: TULCAN | C12: 1 | D12: 1-09 | E12: NARVAEZ CARDENAS ELSSIE MABEL
A13: 10 | B13: TULCAN | C13: 1 | D13: 1-10 | E13: RODRIGUEZ BUSTOS LUCIA GRACIELA
A14: 11 | B14: TULCAN | C14: 1 | D14: 1-11 | E14: DISPONIBLE
A15: 12 | B15: TULCAN | C15: 1 | D15: 1-12 | E15: DISPONIBLE
... A50: 47 | B50: QUITO | C50: 6 | D50: 6-10 | E50: RUANO FLORES ROSA VIRGINIA
B51: QUITO | C51: 6 | D51: 6-11 | E51: ESPINOZA JARAMILLO MARIA EUGENIA
A52: 48 | B52: LAGO AGRIO | C52: 7 | D52: 7-01 | E52: BRAVO ORELLANA LILIANA ELIZABETH
A53: 49 | B53: LAGO AGRIO | C53: 7 | D53: 7-02 | E53: MENDIETA VELEZ TANYI MARIA
A54: 50 | B54: LAGO AGRIO | C54: 7 | D54: 7-03 | E54: JARAMILLO JIMENEZ CARLOS ISRAEL
A55: 51 | B55: LAGO AGRIO | C55: 7 | D55: 7-04 | E55: CHANGO CAMACHO MARCIA VERONICA
A56: 52 | B56: IBARRA AMAZONAS | C56: 8 | D56: 8-01 | E56: FIALLOS GRIJALVA BLANCA RUBY
A57: 53 | B57: IBARRA AMAZONAS | C57: 8 | D57: 8-02 | E57: HERNANDEZ CHACUA AURA SUSANA
A58: 54 | B58: IBARRA AMAZONAS | C58: 8 | D58: 8-03 | E58: ALBAN ARCOS SEBASTIAN LEONARDO
A59: 55 | B59: IBARRA AMAZONAS | C59: 8 | D59: 8-04 | E59: MORETA CACUANGO JUANA XIMENA
A60: 56 | B60: IBARRA AMAZONAS | C60: 8 | D60: 8-05 | E60: CRIOLLO SANDOVAL LUISA GIOCONDA
A61: 57 | B61: IBARRA AMAZONAS | C61: 8 | D61: 8-06 | E61: URCUANGO YACELGA JORGE IVAN
B62: IBARRA AMAZONAS | C62: 8 | D62: 8-07 | E62: BOLAÑOS BASTIDAS PAUL ALEJANDRO
B63: IBARRA AMAZONAS | C63: 8 | D63: 8-08 | E63: CONDOR TUTILLO MAYRA ALEJANDRA
A64: 58 | B64: IBARRA MAYORISTA | C64: 9 | D64: 9-01 | E64: MORILLO POZO IRENE PATRICIA
A65: 59 | B65: IBARRA MAYORISTA | C65: 9 | D65: 9-02 | E65: BOLAÑOS ITAS ESTEBAN FABRICIO
A66: 60 | B66: ATUNTAQUI | C66: 10 | D66: 10-01 | E66: ARTIEDA CHUMA KARINA GABRIELA
A67: 61 | B67: ATUNTAQUI | C67: 10 | D67: 10-02 | E67: MONTALVO ENDARA MARCO ANTONIO
A68: 62 | B68: ATUNTAQUI | C68: 10 | D68: 10-03 | E68: MONTENEGRO LOPEZ KATHERINE FERNANDA
A69: 63 | B69: ATUNTAQUI | C69: 10 | D69: 10-04 | E69: TERAN POSSO SILVIA VANESSA
A70: 64 | B70: ATUNTAQUI | C70: 10 | D70: 10-05 | E70: IBADANGO SANCHEZ SONIA MARLENE
A71: 65 | B71: OTAVALO | C71: 11 | D71: 11-01 | E71: BENALCAZAR CHULDE EDWIN RENE
A72: 66 | B72: OTAVALO | C72: 11 | D72: 11-02 | E72: PAREDES GRANIZO MARCO PATRICIO
A73: 67 | B73: OTAVALO | C73: 11 | D73: 11-03 | E73: LOPEZ CAMUENDO CRISTINA DEL CARMEN
A74: 68 | B74: OTAVALO | C74: 11 | D74: 11-04 | E74: PAREDES ALMEIDA LUIS ANDRES
A75: 69 | B75: OTAVALO | C75: 11 | D75: 11-05 | E75: FLORES BETANCOURT DIANA CAROLINA
... A92: 87 | B92: TUMBACO | C92: 14 | D92: 14-08 | E92: ALMEIDA PIEDRA JOSSELIN FERNANDA
...

Sheet TIPOS DE PRÉSTAMO
A1: TIPO DE PRÉSTAMO
A2: 1 | B2: A EMPLEADOS Y DIRECTIVOS ORDINARIO
A3: 1-01 | B3: A EMPLEADOS Y DIRECTIVOS ORDINARIO NOVADO REFINANCIADO REESTRUCTURADO
A4: 2 | B4: A PROFESIONALES DE LA CONSTRUCCION
A5: 2-01 | B5: A PROFESIONALES DE LA CONSTRUCCION NOVADO REFINANCIADO REESTRUCTURADO
A6: 3 | B6: CREDITO EDUCATIVO
A7: 3-01 | B7: CREDITO EDUCATIVO NOVADO REFINANCIADO REESTRUCTURADO
A8: 4 | B8: ORDINARIO SIN GARANTE
A9: 4-01 | B9: ORDINARIO SIN GARANTE NOVADO REFINANCIADO REESTRUCTURADO
A10: 5 | B10: ESPECIAL A INSTITUCIONES ORDINARIO
A11: 5-01 | B11: ESPECIAL INSTITUCIONES ORDINARIO NOVADO REFINANCIADO REESTRUCTURADO
A12: 6 | B12: ESPECIAL INSTITUCIONES HIPOTECARIO
A13: 6-01 | B13: ESPECIAL INSTITUCIONES HIPOTECARIO NOVADO REFINANCIADO REESTRUCTURADO
... A44: 29 | B44: CRÉDITO POST SIN GARANTE

Sheet  Seguro de Desgravamen Tit+Cony
A6: Cálculo del Seguro de Desgravamen
A8: CAPITAL | B8: 100000
A9: INTERES | B9: 0.14
A10: PLAZO | B10: 84
A11: PAGO POR AÑO | B11: 12 | C11: CUOTA FIJA | D11: =+B8/((1-(1+B13)^-B10)/B13) -> 1874.0012
A12: FRECUENCIA | B12: 30
A13: INTERES MENSUAL | B13: =+B9/B11 -> 0.011666667 | C13: VALOR TOTAL SEGURO | D13: =SUMIF(M19:M198,">0",M19:M198) -> 6039.5173
A14: INTERES DIARIO | B14: =+B9/360 -> 0.00038888889
A15: TASA NETA SEGURO | B15: 0.0118
A17: CUOTA | B17: FECHA | C17: CAPITAL | D17: INTERES | E17: DIAS | F17: CUOTAFIJA | G17: CUOTA+ SEGURO | H17: SALDO | J17: Seguro | K17: Aporte Seps | L17: Seg. Campesivo | M17: Total seguro
B18: =NOW() -> 46079.336 | H18: =+B8 -> 100000 | J18: 0.00118 | K18: 0.035 | L18: 0.005 | M18: =+J18+K18+L18 -> 0.04118
A19: 1 | B19: =+B18+E19 -> 46109.336 | C19: =+$D$11-D19 -> 707.33449 | D19: =+H18*$B$9/360*E19 -> 1166.6667 | E19: 30 | F19: =+C19+D19 -> 1874.0012 | G19: =+F19+M19 -> 1996.7212 | H19: =+H18-C19 -> 99292.666 | J19: =+H18*$J$18 -> 118 | K19: =+J19*$K$18 -> 4.13 | L19: =+J19*$L$18 -> 0.59 | M19: =+J19+K19+L19 -> 122.72
A20: 2 | B20: =+B19+E20 -> 46139.336 | C20: =+$D$11-D20 -> 715.58673 | D20: =+H19*$B$9/360*E20 -> 1158.4144 | E20: 30 | F20: =+C20+D20 -> 1874.0012 | G20: =+F20+M20 -> 1995.8531 | H20: =+H19-C20 -> 98577.079 | J20: =+H19*$J$18 -> 117.16535 | K20: =+J20*$K$18 -> 4.1007871 | L20: =+J20*$L$18 -> 0.58582673 | M20: =+J20+K20+L20 -> 121.85196
A21: 3 | B21: =+B20+E21 -> 46169.336 | C21: =+$D$11-D21 -> 723.93524 | D21: =+H20*$B$9/360*E21 -> 1150.0659 | E21: 30 | F21: =+C21+D21 -> 1874.0012 | G21: =+F21+M21 -> 1994.975 | H21: =+H20-C21 -> 97853.144 | J21: =+H20*$J$18 -> 116.32095 | K21: =+J21*$K$18 -> 4.0712334 | L21: =+J21*$L$18 -> 0.58160476 | M21: =+J21+K21+L21 -> 120.97379
A22: 4 | B22: =NOW() -> 46079.336 | C22: =+$D$11-D22 -> 732.38115 | D22: =+H21*$B$9/360*E22 -> 1141.62 | E22: 30 | F22: =+C22+D22 -> 1874.0012 | G22: =+F22+M22 -> 1994.0865 | H22: =+H21-C22 -> 97120.762 | J22: =+H21*$J$18 -> 115.46671 | K22: =+J22*$K$18 -> 4.0413348 | L22: =+J22*$L$18 -> 0.57733355 | M22: =+J22+K22+L22 -> 120.08538
A23: 5 | B23: =+B22+E23 -> 46109.336 | C23: =+$D$11-D23 -> 740.9256 | D23: =+H22*$B$9/360*E23 -> 1133.0756 | E23: 30 | F23: =+C23+D23 -> 1874.0012 | G23: =+F23+M23 -> 1993.1878 | H23: =+H22-C23 -> 96379.837 | J23: =+H22*$J$18 -> 114.6025 | K23: =+J23*$K$18 -> 4.0110875 | L23: =+J23*$L$18 -> 0.5730125 | M23: =+J23+K23+L23 -> 119.1866
A24: 6 | B24: =+B23+E24 -> 46139.336 | C24: =+$D$11-D24 -> 749.56973 | D24: =+H23*$B$9/360*E24 -> 1124.4314 | E24: 30 | F24: =+C24+D24 -> 1874.0012 | G24: =+F24+M24 -> 1992.2785 | H24: =+H23-C24 -> 95630.267 | J24: =+H23*$J$18 -> 113.72821 | K24: =+J24*$K$18 -> 3.9804873 | L24: =+J24*$L$18 -> 0.56864104 | M24: =+J24+K24+L24 -> 118.27734
A25: 7 | B25: =+B24+E25 -> 46169.336 | C25: =+$D$11-D25 -> 758.31471 | D25: =+H24*$B$9/360*E25 -> 1115.6864 | E25: 30 | F25: =+C25+D25 -> 1874.0012 | G25: =+F25+M25 -> 1991.3586 | H25: =+H24-C25 -> 94871.952 | J25: =+H24*$J$18 -> 112.84372 | K25: =+J25*$K$18 -> 3.94953 | L25: =+J25*$L$18 -> 0.56421858 | M25: =+J25+K25+L25 -> 117.35746
A26: 8 | B26: =NOW() -> 46079.336 | C26: =+$D$11-D26 -> 767.16172 | D26: =+H25*$B$9/360*E26 -> 1106.8394 | E26: 30 | F26: =+C26+D26 -> 1874.0012 | G26: =+F26+M26 -> 1990.428 | H26: =+H25-C26 -> 94104.791 | J26: =+H25*$J$18 -> 111.9489 | K26: =+J26*$K$18 -> 3.9182116 | L26: =+J26*$L$18 -> 0.55974452 | M26: =+J26+K26+L26 -> 116.42686
A27: 9 | B27: =+B26+E27 -> 46109.336 | C27: =+$D$11-D27 -> 776.11194 | D27: =+H26*$B$9/360*E27 -> 1097.8892 | E27: 30 | F27: =+C27+D27 -> 1874.0012 | G27: =+F27+M27 -> 1989.4866 | H27: =+H26-C27 -> 93328.679 | J27: =+H26*$J$18 -> 111.04365 | K27: =+J27*$K$18 -> 3.8865279 | L27: =+J27*$L$18 -> 0.55521826 | M27: =+J27+K27+L27 -> 115.4854
A28: 10 | B28: =+B27+E28 -> 46139.336 | C28: =+$D$11-D28 -> 785.16658 | D28: =+H27*$B$9/360*E28 -> 1088.8346 | E28: 30 | F28: =+C28+D28 -> 1874.0012 | G28: =+F28+M28 -> 1988.5341 | H28: =+H27-C28 -> 92543.512 | J28: =+H27*$J$18 -> 110.12784 | K28: =+J28*$K$18 -> 3.8544744 | L28: =+J28*$L$18 -> 0.5506392 | M28: =+J28+K28+L28 -> 114.53295
A29: 11 | B29: =+B28+E29 -> 46169.336 | C29: =+$D$11-D29 -> 794.32685 | D29: =+H28*$B$9/360*E29 -> 1079.6743 | E29: 30 | F29: =+C29+D29 -> 1874.0012 | G29: =+F29+M29 -> 1987.5706 | H29: =+H28-C29 -> 91749.185 | J29: =+H28*$J$18 -> 109.20134 | K29: =+J29*$K$18 -> 3.8220471 | L29: =+J29*$L$18 -> 0.54600672 | M29: =+J29+K29+L29 -> 113.5694
A30: 12 | B30: =NOW() -> 46079.336 | C30: =+$D$11-D30 -> 803.594 | D30: =+H29*$B$9/360*E30 -> 1070.4072 | E30: 30 | F30: =+C30+D30 -> 1874.0012 | G30: =+F30+M30 -> 1986.5958 | H30: =+H29-C30 -> 90945.591 | J30: =+H29*$J$18 -> 108.26404 | K30: =+J30*$K$18 -> 3.7892414 | L30: =+J30*$L$18 -> 0.54132019 | M30: =+J30+K30+L30 -> 112.5946
A31: 13 | B31: =+B30+E31 -> 46109.336 | C31: =+$D$11-D31 -> 812.96926 | D31: =+H30*$B$9/360*E31 -> 1061.0319 | E31: 30 | F31: =+C31+D31 -> 1874.0012 | G31: =+F31+M31 -> 1985.6096 | H31: =+H30-C31 -> 90132.622 | J31: =+H30*$J$18 -> 107.3158 | K31: =+J31*$K$18 -> 3.7560529 | L31: =+J31*$L$18 -> 0.53657899 | M31: =+J31+K31+L31 -> 111.60843
A32: 14 | B32: =+B31+E32 -> 46139.336 | C32: =+$D$11-D32 -> 822.4539 | D32: =+H31*$B$9/360*E32 -> 1051.5473 | E32: 30 | F32: =+C32+D32 -> 1874.0012 | G32: =+F32+M32 -> 1984.6119 | H32: =+H31-C32 -> 89310.168 | J32: =+H31*$J$18 -> 106.35649 | K32: =+J32*$K$18 -> 3.7224773 | L32: =+J32*$L$18 -> 0.53178247 | M32: =+J32+K32+L32 -> 110.61075
A33: 15 | B33: =+B32+E33 -> 46169.336 | C33: =+$D$11-D33 -> 832.0492 | D33: =+H32*$B$9/360*E33 -> 1041.952 | E33: 30 | F33: =+C33+D33 -> 1874.0012 | G33: =+F33+M33 -> 1983.6026 | H33: =+H32-C33 -> 88478.119 | J33: =+H32*$J$18 -> 105.386 | K33: =+J33*$K$18 -> 3.6885099 | L33: =+J33*$L$18 -> 0.52692999 | M33: =+J33+K33+L33 -> 109.60144
A34: 16 | B34: =NOW() -> 46079.336 | C34: =+$D$11-D34 -> 841.75644 | D34: =+H33*$B$9/360*E34 -> 1032.2447 | E34: 30 | F34: =+C34+D34 -> 1874.0012 | G34: =+F34+M34 -> 1982.5815 | H34: =+H33-C34 -> 87636.362 | J34: =+H33*$J$18 -> 104.40418 | K34: =+J34*$K$18 -> 3.6541463 | L34: =+J34*$L$18 -> 0.5220209 | M34: =+J34+K34+L34 -> 108.58035
A35: 17 | B35: =+B34+E35 -> 46109.336 | C35: =+$D$11-D35 -> 851.57693 | D35: =+H34*$B$9/360*E35 -> 1022.4242 | E35: 30 | F35: =+C35+D35 -> 1874.0012 | G35: =+F35+M35 -> 1981.5485 | H35: =+H34-C35 -> 86784.786 | J35: =+H34*$J$18 -> 103.41091 | K35: =+J35*$K$18 -> 3.6193818 | L35: =+J35*$L$18 -> 0.51705454 | M35: =+J35+K35+L35 -> 107.54734
A36: 18 | B36: =+B35+E36 -> 46139.336 | C36: =+$D$11-D36 -> 861.512 | D36: =+H35*$B$9/360*E36 -> 1012.4892 | E36: 30 | F36: =+C36+D36 -> 1874.0012 | G36: =+F36+M36 -> 1980.5034 | H36: =+H35-C36 -> 85923.274 | J36: =+H35*$J$18 -> 102.40605 | K36: =+J36*$K$18 -> 3.5842116 | L36: =+J36*$L$18 -> 0.51203023 | M36: =+J36+K36+L36 -> 106.50229
A37: 19 | B37: =+B36+E37 -> 46169.336 | C37: =+$D$11-D37 -> 871.56297 | D37: =+H36*$B$9/360*E37 -> 1002.4382 | E37: 30 | F37: =+C37+D37 -> 1874.0012 | G37: =+F37+M37 -> 1979.4462 | H37: =+H36-C37 -> 85051.711 | J37: =+H36*$J$18 -> 101.38946 | K37: =+J37*$K$18 -> 3.5486312 | L37: =+J37*$L$18 -> 0.50694731 | M37: =+J37+K37+L37 -> 105.44504
A38: 20 | B38: =NOW() -> 46079.336 | C38: =+$D$11-D38 -> 881.7312 | D38: =+H37*$B$9/360*E38 -> 992.26996 | E38: 30 | F38: =+C38+D38 -> 1874.0012 | G38: =+F38+M38 -> 1978.3766 | H38: =+H37-C38 -> 84169.979 | J38: =+H37*$J$18 -> 100.36102 | K38: =+J38*$K$18 -> 3.5126356 | L38: =+J38*$L$18 -> 0.50180509 | M38: =+J38+K38+L38 -> 104.37546
A39: 21 | B39: =+B38+E39 -> 46109.336 | C39: =+$D$11-D39 -> 892.01807 | D39: =+H38*$B$9/360*E39 -> 981.98309 | E39: 30 | F39: =+C39+D39 -> 1874.0012 | G39: =+F39+M39 -> 1977.2946 | H39: =+H38-C39 -> 83277.961 | J39: =+H38*$J$18 -> 99.320576 | K39: =+J39*$K$18 -> 3.4762201 | L39: =+J39*$L$18 -> 0.49660288 | M39: =+J39+K39+L39 -> 103.2934
A40: 22 | B40: =+B39+E40 -> 46139.336 | C40: =+$D$11-D40 -> 902.42495 | D40: =+H39*$B$9/360*E40 -> 971.57621 | E40: 30 | F40: =+C40+D40 -> 1874.0012 | G40: =+F40+M40 -> 1976.1999 | H40: =+H39-C40 -> 82375.536 | J40: =+H39*$J$18 -> 98.267994 | K40: =+J40*$K$18 -> 3.4393798 | L40: =+J40*$L$18 -> 0.49133997 | M40: =+J40+K40+L40 -> 102.19871
A41: 23 | B41: =+B40+E41 -> 46169.336 | C41: =+$D$11-D41 -> 912.95324 | D41: =+H40*$B$9/360*E41 -> 961.04792 | E41: 30 | F41: =+C41+D41 -> 1874.0012 | G41: =+F41+M41 -> 1975.0924 | H41: =+H40-C41 -> 81462.583 | J41: =+H40*$J$18 -> 97.203133 | K41: =+J41*$K$18 -> 3.4021097 | L41: =+J41*$L$18 -> 0.48601566 | M41: =+J41+K41+L41 -> 101.09126
A42: 24 | B42: =NOW() -> 46079.336 | C42: =+$D$11-D42 -> 923.60436 | D42: =+H41*$B$9/360*E42 -> 950.3968 | E42: 30 | F42: =+C42+D42 -> 1874.0012 | G42: =+F42+M42 -> 1973.972 | H42: =+H41-C42 -> 80538.979 | J42: =+H41*$J$18 -> 96.125848 | K42: =+J42*$K$18 -> 3.3644047 | L42: =+J42*$L$18 -> 0.48062924 | M42: =+J42+K42+L42 -> 99.970882
A43: 25 | B43: =NOW() -> 46079.336 | C43: =+$D$11-D43 -> 934.37974 | D43: =+H42*$B$9/360*E43 -> 939.62142 | E43: 30 | F43: =+C43+D43 -> 1874.0012 | G43: =+F43+M43 -> 1972.8386 | H43: =+H42-C43 -> 79604.599 | J43: =+H42*$J$18 -> 95.035995 | K43: =+J43*$K$18 -> 3.3262598 | L43: =+J43*$L$18 -> 0.47517997 | M43: =+J43+K43+L43 -> 98.837435
A44: 26 | B44: =+B43+E44 -> 46109.336 | C44: =+$D$11-D44 -> 945.28084 | D44: =+H43*$B$9/360*E44 -> 928.72032 | E44: 30 | F44: =+C44+D44 -> 1874.0012 | G44: =+F44+M44 -> 1971.6919 | H44: =+H43-C44 -> 78659.318 | J44: =+H43*$J$18 -> 93.933427 | K44: =+J44*$K$18 -> 3.2876699 | L44: =+J44*$L$18 -> 0.46966713 | M44: =+J44+K44+L44 -> 97.690764
A45: 27 | B45: =+B44+E45 -> 46139.336 | C45: =+$D$11-D45 -> 956.30912 | D45: =+H44*$B$9/360*E45 -> 917.69205 | E45: 30 | F45: =+C45+D45 -> 1874.0012 | G45: =+F45+M45 -> 1970.5319 | H45: =+H44-C45 -> 77703.009 | J45: =+H44*$J$18 -> 92.817995 | K45: =+J45*$K$18 -> 3.2486298 | L45: =+J45*$L$18 -> 0.46408998 | M45: =+J45+K45+L45 -> 96.530715
